Workbook

Sheet Data Analysis 
A1: Subject | B1: ES1 | C1: ES2 | E1: KEY | G1: Subject | H1: 1st b | I1: 1st s | J1: 2nd b | K1: 2nd s | L1: 3rd b | M1: 3rd s | N1: 4th b | O1: 4th s | P1: 5th b | Q1: 5th s | R1: 6ht b | S1: 6th s | T1: 7th b | U1: 7th s | V1: 8th b | W1: 8th s | X1: 9th b | Y1: 9th s | Z1: 10th b | AA1: 10th s | AC1: NOTE:
A2: 1001 | B2: 0.16382 | C2: 0.15044 | E2: ES1: First 5 trials | G2: 1001 | H2: 0.13173 | I2: 0.14627 | J2: 0.11660398 | K2: 0.32475383 | L2: 0.090370552 | M2: 0.16119418 | N2: 0.13229509 | O2: 0.13213199 | P2: 0.10434547 | Q2: 0.13603122 | R2: 0.15963656 | S2: 0.12205659 | T2: 0.16085642 | U2: 0.23543695 | V2: 0.26858141 | W2: 0.09918975 | X2: 0.15802816 | Y2: =AVERAGE('Raw Error Scores'!C35:C37) -> 0.11819432 | Z2: 0.15962206 | AA2: 0.12578099 | AC2: Dec 8th for tenth set
A3: 1002 | B3: 0.12205 | C3: 0.14691 | E3: ES2: 2nd 5 trials | G3: 1002 | H3: 0.13505 | I3: 0.089098 | J3: 0.11818617 | K3: 0.09916655 | L3: 0.1802386 | M3: 0.11681234 | N3: 0.14626103 | O3: 0.10243395 | P3: 0.17171695 | Q3: 0.15564102 | R3: 0.28593262 | S3: 0.16049722 | T3: 0.18884495 | U3: 0.13641691 | V3: 0.1660469 | W3: 0.12191336 | X3: 0.1185581 | Y3: =AVERAGE('Raw Error Scores'!D35:D37) -> 0.10656736 | Z3: 0.090679093 | AA3: 0.170635 | AC3: Dec 15th for the rest
A4: 1003 | B4: 0.10931 | C4: 0.125 | G4: 1003 | H4: 0.1234 | I4: 0.10597 | J4: 0.13105264 | K4: 0.089138804 | L4: 0.07670827 | M4: 0.12417228 | N4: 0.096860685 | O4: 0.11265466 | P4: 0.13342216 | Q4: 0.10967538 | R4: 0.14854035 | S4: 0.11244236 | T4: 0.097093793 | U4: 0.13338075 | V4: 0.12880761 | W4: 0.10059238 | X4: 0.1942474 | Y4: =AVERAGE('Raw Error Scores'!E35:E37) -> 0.13183299 | Z4: 0.13287769 | AA4: 0.12125369
A5: 1004 | B5: 0.10918 | C5: 0.14165 | E5: OBSERVATION (AM)7/25/2024 | G5: 1004 | H5: 0.15713 | I5: 0.095864 | J5: 0.11182575 | K5: 0.10456119 | L5: 0.10825938 | M5: 0.094550564 | N5: 0.15204033 | O5: 0.11730723 | P5: 0.11773584 | Q5: 0.099938834 | R5: 0.20428442 | S5: 0.13535627 | T5: 0.29777461 | U5: 0.14908646 | V5: 0.17166907 | W5: 0.11668596 | X5: 0.15634473 | Y5: =AVERAGE('Raw Error Scores'!F35:F37) -> 0.1191476 | Z5: 0.091094742 | AA5: 0.117033
A6: 1005 | B6: 0.17904 | C6: 0.17418 | E6: The right green/blue columns are averaging the small | G6: 1005 | H6: 0.24656 | I6: 0.15306 | J6: 0.22558313 | K6: 0.12745193 | L6: 0.14854598 | M6: 0.20138201 | N6: 0.32167207 | O6: 0.12107167 | P6: 0.2835267 | Q6: 0.18202633 | R6: 0.30996387 | S6: 0.15720779 | T6: 0.19711092 | U6: 0.12764205 | V6: 0.22993667 | W6: 0.17371452 | X6: 0.17911651 | Y6: =AVERAGE('Raw Error Scores'!G35:G37) -> 0.15926446 | Z6: 0.21262054 | AA6: 0.16715493
A7: 1006 | B7: 0.12441 | C7: 0.11507 | E7: circles twice impacting the soundness of data. | G7: 1006 | H7: 0.14108 | I7: 0.10766 | J7: 0.095371029 | K7: 0.12448519 | L7: 0.11994663 | M7: 0.11024646 | N7: 0.21010114 | O7: 0.12198589 | P7: 0.2033395 | Q7: 0.10841498 | R7: 0.14015374 | S7: 0.10457118 | T7: 0.14131092 | U7: 0.085181265 | V7: 0.098478455 | W7: 0.12901223 | X7: 0.10739508 | Y7: =AVERAGE('Raw Error Scores'!H35:H37) -> 0.11424765 | Z7: 0.15408767 | AA7: 0.12033245
A8: 1009 | B8: 0.16418 | C8: 0.13674 | G8: 1009 | H8: 0.13265 | I8: 0.20683 | J8: 0.11136392 | K8: 0.14068501 | L8: 0.091864787 | M8: 0.18594631 | N8: 0.087749839 | O8: 0.20612471 | P8: 0.12144113 | Q8: 0.17322783 | R8: 0.10911064 | S8: 0.18867688 | T8: 0.092280788 | U8: 0.14440798 | V8: 0.061224072 | W8: 0.14575076 | X8: 0.11219267 | Y8: =AVERAGE('Raw Error Scores'!I35:I37) -> 0.13201066 | Z8: 0.065775546 | AA8: 0.15388975
A9: 2001 | B9: 0.15611 | C9: 0.15355 | E9: The highlighted columns on the left have averaged | G9: 2001 | H9: 0.19984 | I9: 0.13542 | J9: 0.14678328 | K9: 0.13985097 | L9: 0.22878195 | M9: 0.17016189 | N9: 0.14922342 | O9: 0.11533752 | P9: 0.26979082 | Q9: 0.14849133 | R9: 0.2059181 | S9: 0.15384934 | T9: 0.134352 | U9: 0.2138491 | V9: 0.098045124 | W9: 0.13500656 | X9: 0.11231239 | Y9: =AVERAGE('Raw Error Scores'!J35:J37) -> 0.13468819 | Z9: 0.16600645 | AA9: 0.14742635
A10: 2002 | B10: 0.088491 | C10: 0.1098 | E10: big and small circles once that is averaging all four at once. | G10: 2002 | H10: 0.091655 | I10: 0.11662 | J10: 0.048680984 | K10: 0.076144304 | L10: 0.095660613 | M10: 0.079856268 | N10: 0.091094807 | O10: 0.076662524 | P10: 0.074365012 | Q10: 0.10684025 | R10: 0.11781754 | S10: 0.096927424 | T10: 0.075890064 | U10: 0.090161392 | V10: 0.14253978 | W10: 0.10564417 | X10: 0.11248296 | Y10: =AVERAGE('Raw Error Scores'!K35:K37) -> 0.13247383 | Z10: 0.13195246 | AA10: 0.1132155
A11: 2004 | B11: 0.18533 | C11: 0.16014 | G11: 2004 | H11: 0.2024 | I11: 0.16326 | J11: 0.12164046 | K11: 0.13766919 | L11: 0.23332518 | M11: 0.23806048 | N11: 0.18527961 | O11: 0.2136264 | P11: 0.18882089 | Q11: 0.17242327 | R11: 0.11654828 | S11: 0.18522914 | T11: 0.14017408 | U11: 0.16918576 | V11: 0.16489609 | W11: 0.18522913 | X11: 0.19508766 | Y11: =AVERAGE('Raw Error Scores'!L35:L37) -> 0.1329485 | Z11: 0.10064801 | AA11: 0.15586916
A12: 2005 | B12: 0.18495 | C12: 0.17931 | G12: 2005 | H12: 0.1765 | I12: 0.11942 | J12: 0.12858856 | K12: 0.16917777 | L12: 0.13832724 | M12: 0.26058788 | N12: 0.17572404 | O12: 0.25039571 | P12: 0.18992961 | Q12: 0.16390431 | R12: 0.17644311 | S12: 0.1728671 | T12: 0.17442497 | U12: 0.18308752 | V12: 0.16373005 | W12: 0.17006125 | X12: 0.27261806 | Y12: =AVERAGE('Raw Error Scores'!M35:M37) -> 0.20441319 | Z12: 0.17659158 | AA12: 0.14373446
A13: 2006 | B13: 0.12064 | C13: 0.12399 | G13: 2006 | H13: 0.13405 | I13: 0.1071 | J13: 0.10279871 | K13: 0.1001885 | L13: 0.15485423 | M13: 0.11151524 | N13: 0.14762014 | O13: 0.15360161 | P13: 0.081712948 | Q13: 0.12481939 | R13: 0.10067641 | S13: 0.13525517 | T13: 0.19320702 | U13: 0.11236086 | V13: 0.14528625 | W13: 0.13583429 | X13: 0.09421182 | Y13: =AVERAGE('Raw Error Scores'!N35:N37) -> 0.11243239 | Z13: 0.18738235 | AA13: 0.090482891
A14: 2007 | B14: 0.15223 | C14: 0.15392 | G14: 2007 | H14: 0.21047 | I14: 0.11653 | J14: 0.25759687 | K14: 0.13689528 | L14: 0.18058871 | M14: 0.10466923 | N14: 0.21740526 | O14: 0.12766601 | P14: 0.17498457 | Q14: 0.18207535 | R14: 0.20652609 | S14: 0.12482221 | T14: 0.15808861 | U14: 0.19545634 | V14: 0.10466917 | W14: 0.19050531 | X14: 0.12950889 | Y14: =AVERAGE('Raw Error Scores'!O35:O37) -> 0.13184866 | Z14: 0.13712811 | AA14: 0.13818525
A15: 2008 | B15: 0.28498 | C15: 0.34844 | G15: 2008 | H15: 0.27285 | I15: 0.28989 | J15: 0.26791247 | K15: 0.25202137 | L15: 0.3462945 | M15: 0.39066286 | N15: 0.30377699 | O15: 0.23552297 | P15: 0.36213429 | Q15: 0.21409755 | R15: 0.82047797 | S15: 0.31693426 | T15: 0.38343894 | U15: 0.2562338 | V15: 0.27919553 | W15: 0.27855091 | X15: 0.37437891 | Y15: =AVERAGE('Raw Error Scores'!P35:P37) -> 0.42649504 | Z15: 0.37864767 | AA15: 0.29936061
A16: 2009 | B16: 0.13852 | C16: 0.19771 | G16: 2009 | H16: 0.14009 | I16: 0.095152 | J16: 0.1250578 | K16: 0.11215495 | L16: 0.17185679 | M16: 0.14910484 | N16: 0.17381074 | O16: 0.15281255 | P16: 0.15945766 | Q16: 0.15751059 | R16: 0.23613076 | S16: 0.16571077 | T16: 0.19161681 | U16: 0.2325925 | V16: 0.16440554 | W16: 0.16836271 | X16: 0.13102058 | Y16: =AVERAGE('Raw Error Scores'!Q35:Q37) -> 0.19122395 | Z16: 0.49377684 | AA16: 0.1545336
A17: 2010 | B17: 0.173 | C17: 0.15795 | G17: 2010 | H17: 0.21293 | I17: 0.23843 | J17: 0.18083833 | K17: 0.15817165 | L17: 0.16632603 | M17: 0.15330642 | N17: 0.16682237 | O17: 0.13294717 | P17: 0.27562024 | Q17: 0.13629431 | R17: 0.18557891 | S17: 0.11771573 | T17: 0.1518418 | U17: 0.19128212 | V17: 0.17182321 | W17: 0.18259111 | X17: 0.13226141 | Y17: =AVERAGE('Raw Error Scores'!R35:R37) -> 0.16880361 | Z17: 0.18976709 | AA17: 0.11549518
A18: 2011 | B18: 0.10543 | C18: 0.12021 | G18: 2011 | H18: 0.2399 | I18: 0.11687 | J18: 0.1199853 | K18: 0.10412822 | L18: 0.08731564 | M18: 0.079890111 | N18: 0.10932705 | O18: 0.091248913 | P18: 0.151128 | Q18: 0.074861303 | R18: 0.21180792 | S18: 0.088309495 | T18: 0.09381119 | U18: 0.11486743 | V18: 0.13784741 | W18: 0.12033408 | X18: 0.16124158 | Y18: =AVERAGE('Raw Error Scores'!S35:S37) -> 0.11323019 | Z18: 0.13379227 | AA18: 0.11848339
A19: 2012 | B19: 0.12208 | C19: 0.11276 | G19: 2012 | H19: 0.10697 | I19: 0.1162 | J19: 0.14682842 | K19: 0.12733928 | L19: 0.13520409 | M19: 0.14077872 | N19: 0.13590069 | O19: 0.12253861 | P19: 0.11842008 | Q19: 0.092565587 | R19: 0.090676635 | S19: 0.12422011 | T19: 0.088811666 | U19: 0.1264325 | V19: 0.11126917 | W19: 0.076821415 | X19: 0.11367357 | Y19: =AVERAGE('Raw Error Scores'!T35:T37) -> 0.10144075 | Z19: 0.14618606 | AA19: 0.1392942
A20: 3001 | B20: 0.16219 | C20: 0.1361 | G20: 3001 | H20: 0.20041 | I20: 0.12164 | J20: 0.6238243 | K20: 0.12509809 | L20: 0.11562561 | M20: 0.13197623 | N20: 0.13141047 | O20: 0.15491782 | P20: 0.096200788 | Q20: 0.15850502 | R20: 0.074967808 | S20: 0.10375914 | T20: 0.15615273 | U20: 0.109734 | V20: 0.16361721 | W20: 0.10791633 | X20: 0.22470732 | Y20: =AVERAGE('Raw Error Scores'!U35:U37) -> 0.15193008 | Z20: 0.24043881 | AA20: 0.14738853
A21: 3002 | B21: 0.072056 | C21: 0.072163 | G21: 3002 | H21: 0.1161 | I21: 0.09917 | J21: 0.071840752 | K21: 0.058476522 | L21: 0.086780794 | M21: 0.059376047 | N21: 0.064643194 | O21: 0.058224163 | P21: 0.096616184 | Q21: 0.059853945 | R21: 0.10156955 | S21: 0.059043152 | T21: 0.070950724 | U21: 0.078841367 | V21: 0.1016033 | W21: 0.080121913 | X21: 0.059948545 | Y21: =AVERAGE('Raw Error Scores'!V35:V37) -> 0.068917238 | Z21: 0.079408546 | AA21: 0.056334882
A22: 3003 | B22: 0.10063 | C22: 0.13575 | G22: 3003 | H22: 0.1378 | I22: 0.079647 | J22: 0.15833249 | K22: 0.11055423 | L22: 0.12363267 | M22: 0.080951726 | N22: 0.1084525 | O22: 0.10230061 | P22: 0.088146398 | Q22: 0.091988384 | R22: 0.20896289 | S22: 0.14498672 | T22: 0.15633351 | U22: 0.14269561 | V22: 0.11326037 | W22: 0.11432947 | X22: 0.09804662 | Y22: =AVERAGE('Raw Error Scores'!W35:W37) -> 0.091588892 | Z22: 0.11637358 | AA22: 0.13541572
A23: 3004 | B23: 0.11995 | C23: 0.11531 | G23: 3004 | H23: 0.12795 | I23: 0.087329 | J23: 0.11719123 | K23: 0.10837348 | L23: 0.1265376 | M23: 0.13249842 | N23: 0.11198468 | O23: 0.12646507 | P23: 0.15938051 | Q23: 0.13064742 | R23: 0.13109425 | S23: 0.11011596 | T23: 0.14291883 | U23: 0.082390139 | V23: 0.10444112 | W23: 0.11748596 | X23: 0.15757313 | Y23: =AVERAGE('Raw Error Scores'!X35:X37) -> 0.12300978 | Z23: 0.14309659 | AA23: 0.10935471
A24: 3006 | B24: 0.093253 | C24: 0.089403 | G24: 3006 | H24: 0.097717 | I24: 0.094135 | J24: 0.076118852 | K24: 0.093284152 | L24: 0.090136791 | M24: 0.098099393 | N24: 0.11291232 | O24: 0.070628135 | P24: 0.12503163 | Q24: 0.098231566 | R24: 0.15074487 | S24: 0.079431955 | T24: 0.095674525 | U24: 0.08096267 | V24: 0.079492706 | W24: 0.089093621 | X24: 0.10069733 | Y24: =AVERAGE('Raw Error Scores'!Y35:Y37) -> 0.090355638 | Z24: 0.08823399 | AA24: 0.084563424
A25: 3007 | B25: 0.13578 | C25: 0.15368 | G25: 3007 | H25: 0.18555 | I25: 0.14558 | J25: 0.14887795 | K25: 0.11674445 | L25: 0.13555448 | M25: 0.14080866 | N25: 0.13095824 | O25: 0.11928168 | P25: 0.10124466 | Q25: 0.14870128 | R25: 0.20935405 | S25: 0.13155023 | T25: 0.18531784 | U25: 0.1493043 | V25: 0.14023187 | W25: 0.14691317 | X25: 0.13840529 | Y25: =AVERAGE('Raw Error Scores'!Z35:Z37) -> 0.13783138 | Z25: 0.1796951 | AA25: 0.17456663
A26: 3008 | B26: 0.12948 | C26: 0.1848 | G26: 3008 | H26: 0.17235 | I26: 0.13288 | J26: 0.12147274 | K26: 0.10152027 | L26: 0.12705254 | M26: 0.11650265 | N26: 0.10465615 | O26: 0.11284738 | P26: 0.15117422 | Q26: 0.1738568 | R26: 0.1278466 | S26: 0.09035102 | T26: 0.18195879 | U26: 0.13958659 | V26: 0.12411984 | W26: 0.16947274 | X26: 0.61428454 | Y26: =AVERAGE('Raw Error Scores'!AA35:AA37) -> 0.19844423 | Z26: 0.27787931 | AA26: 0.19211075
A27: 3009 | B27: 0.11048 | C27: 0.13315 | G27: 3009 | H27: 0.11922 | I27: 0.090125 | J27: 0.085138548 | K27: 0.13282311 | L27: 0.088576429 | M27: 0.10426976 | N27: 0.12202748 | O27: 0.1134613 | P27: 0.1636099 | Q27: 0.10298735 | R27: 0.098785019 | S27: 0.11291991 | T27: 0.11959645 | U27: 0.15013738 | V27: 0.17441309 | W27: 0.14275527 | X27: 0.10775339 | Y27: =AVERAGE('Raw Error Scores'!AB35:AB37) -> 0.151184 | Z27: 0.099067671 | AA27: 0.13081351
A28: 3010 | B28: 0.18374 | C28: 0.16502 | G28: 3010 | H28: 0.22442 | I28: 0.21016 | J28: 0.15481048 | K28: 0.15177925 | L28: 0.18934177 | M28: 0.17467386 | N28: 0.19179275 | O28: 0.22831122 | P28: 0.1765669 | Q28: 0.1477282 | R28: 0.23297713 | S28: 0.22532013 | T28: 0.11364567 | U28: 0.15077679 | V28: 0.22562471 | W28: 0.14494374 | X28: 0.16015399 | Y28: =AVERAGE('Raw Error Scores'!AC35:AC37) -> 0.12544488 | Z28: 0.14258311 | AA28: 0.1620023
A29: 3011 | B29: 0.089872 | C29: 0.085639 | G29: 3011 | H29: 0.10243 | I29: 0.081282 | J29: 0.078812422 | K29: 0.080581954 | L29: 0.11171322 | M29: 0.086382028 | N29: 0.11781258 | O29: 0.090392123 | P29: 0.12180504 | Q29: 0.082985105 | R29: 0.1015479 | S29: 0.089109689 | T29: 0.11578064 | U29: 0.072626496 | V29: 0.070103976 | W29: 0.085487154 | X29: 0.096784439 | Y29: =AVERAGE('Raw Error Scores'!AD35:AD37) -> 0.077228106 | Z29: 0.10907946 | AA29: 0.082040981
A30: 3012 | B30: 0.14407 | C30: 0.17148 | G30: 3012 | H30: 0.16353 | I30: 0.11335 | J30: 0.2061542 | K30: 0.12996617 | L30: 0.094027623 | M30: 0.11378859 | N30: 0.19996867 | O30: 0.16034732 | P30: 0.16026543 | Q30: 0.16836344 | R30: 0.1880069 | S30: 0.18681558 | T30: 0.13936784 | U30: 0.16719642 | V30: 0.15296993 | W30: 0.17740877 | X30: 0.13507815 | Y30: =AVERAGE('Raw Error Scores'!AE35:AE37) -> 0.17887451 | Z30: 0.16692135 | AA30: 0.17211732

Sheet ES for ALL
A1: Average Error Scores for 1st 5 trials (ES1)
A2: and 2nd 5 trials (ES2) :
A3: (THIS IS FOR ALL 4 CIRCLES TOGETHER)
A4: Subject | B4: ES1 (1-5) | C4: ES2 (6-10)
A5: 1001 | B5: 0.16382 | C5: 0.15044
A6: 1002 | B6: 0.12205 | C6: 0.14691
A7: 1003 | B7: 0.10931 | C7: 0.125
A8: 1004 | B8: 0.10918 | C8: 0.14165
A9: 1005 | B9: 0.17904 | C9: 0.17418
A10: 1006 | B10: 0.12441 | C10: 0.11507
A11: 1009 | B11: 0.16418 | C11: 0.13674
A12: 2001 | B12: 0.15611 | C12: 0.15355
A13: 2002 | B13: 0.088491 | C13: 0.1098
A14: 2004 | B14: 0.18533 | C14: 0.16014
A15: 2005 | B15: 0.18495 | C15: 0.17931
A16: 2006 | B16: 0.12064 | C16: 0.12399
... A33: 3012 | B33: 0.14407 | C33: 0.17148
A35: *Overall Avg | B35: =AVERAGE(B5:B33) -> 0.13880179 | C35: =AVERAGE(C5:C33) -> 0.14656086

Sheet ALL 10 Trials - BIG
A1: Subject | B1: 1 - big | C1: 2 - big | D1: 3 - big | E1: 4 - big | F1: 5 - big | G1: AVERAGE ES1 | H1: *Overall Avg | J1: 6 - big | K1: 7 - big | L1: 8 - big | M1: 9 - big | N1: 10 - big | O1: AVERAGE ES2 | P1: *Overall Avg
A2: 1001 | B2: 0.13173304 | C2: 0.11660398 | D2: 0.090370552 | E2: 0.13229509 | F2: 0.10434547 | G2: =AVERAGE(B2:F2) -> 0.11506963 | H2: =AVERAGE(G2:G30) -> 0.15287576 | J2: 0.15963656 | K2: 0.16085642 | L2: 0.26858141 | M2: 0.15802816 | N2: 0.15962206 | O2: =AVERAGE(J2:N2) -> 0.18134492 | P2: =AVERAGE(O2:O30) -> 0.16336941
A3: 1002 | B3: 0.13504829 | C3: 0.11818617 | D3: 0.1802386 | E3: 0.14626103 | F3: 0.17171695 | G3: =AVERAGE(B3:F3) -> 0.15029021 | J3: 0.28593262 | K3: 0.18884495 | L3: 0.1660469 | M3: 0.1185581 | N3: 0.090679093 | O3: =AVERAGE(J3:N3) -> 0.17001233
A4: 1003 | B4: 0.12339935 | C4: 0.13105264 | D4: 0.07670827 | E4: 0.096860685 | F4: 0.13342216 | G4: =AVERAGE(B4:F4) -> 0.11228862 | J4: 0.14854035 | K4: 0.097093793 | L4: 0.12880761 | M4: 0.1942474 | N4: 0.13287769 | O4: =AVERAGE(J4:N4) -> 0.14031337
A5: 1004 | B5: 0.15713296 | C5: 0.11182575 | D5: 0.10825938 | E5: 0.15204033 | F5: 0.11773584 | G5: =AVERAGE(B5:F5) -> 0.12939885 | J5: 0.20428442 | K5: 0.29777461 | L5: 0.17166907 | M5: 0.15634473 | N5: 0.091094742 | O5: =AVERAGE(J5:N5) -> 0.18423352
A6: 1005 | B6: 0.24656209 | C6: 0.22558313 | D6: 0.14854598 | E6: 0.32167207 | F6: 0.2835267 | G6: =AVERAGE(B6:F6) -> 0.24517799 | J6: 0.30996387 | K6: 0.19711092 | L6: 0.22993667 | M6: 0.17911651 | N6: 0.21262054 | O6: =AVERAGE(J6:N6) -> 0.22574971
A7: 1006 | B7: 0.14107662 | C7: 0.095371029 | D7: 0.11994663 | E7: 0.21010114 | F7: 0.2033395 | G7: =AVERAGE(B7:F7) -> 0.15396698 | J7: 0.14015374 | K7: 0.14131092 | L7: 0.098478455 | M7: 0.10739508 | N7: 0.15408767 | O7: =AVERAGE(J7:N7) -> 0.12828517
A8: 1009 | B8: 0.13265165 | C8: 0.11136392 | D8: 0.091864787 | E8: 0.087749839 | F8: 0.12144113 | G8: =AVERAGE(B8:F8) -> 0.10901426 | J8: 0.10911064 | K8: 0.092280788 | L8: 0.061224072 | M8: 0.11219267 | N8: 0.065775546 | O8: =AVERAGE(J8:N8) -> 0.088116743
A9: 2001 | B9: 0.19984035 | C9: 0.14678328 | D9: 0.22878195 | E9: 0.14922342 | F9: 0.26979082 | G9: =AVERAGE(B9:F9) -> 0.19888396 | J9: 0.2059181 | K9: 0.134352 | L9: 0.098045124 | M9: 0.11231239 | N9: 0.16600645 | O9: =AVERAGE(J9:N9) -> 0.14332681
A10: 2002 | B10: 0.091655251 | C10: 0.048680984 | D10: 0.095660613 | E10: 0.091094807 | F10: 0.074365012 | G10: =AVERAGE(B10:F10) -> 0.080291334 | J10: 0.11781754 | K10: 0.075890064 | L10: 0.14253978 | M10: 0.11248296 | N10: 0.13195246 | O10: =AVERAGE(J10:N10) -> 0.11613656
A11: 2004 | B11: 0.20239901 | C11: 0.12164046 | D11: 0.23332518 | E11: 0.18527961 | F11: 0.18882089 | G11: =AVERAGE(B11:F11) -> 0.18629303 | J11: 0.11654828 | K11: 0.14017408 | L11: 0.16489609 | M11: 0.19508766 | N11: 0.10064801 | O11: =AVERAGE(J11:N11) -> 0.14347083
A12: 2005 | B12: 0.17650195 | C12: 0.12858856 | D12: 0.13832724 | E12: 0.17572404 | F12: 0.18992961 | G12: =AVERAGE(B12:F12) -> 0.16181428 | J12: 0.17644311 | K12: 0.17442497 | L12: 0.16373005 | M12: 0.27261806 | N12: 0.17659158 | O12: =AVERAGE(J12:N12) -> 0.19276155
A13: 2006 | B13: 0.13405422 | C13: 0.10279871 | D13: 0.15485423 | E13: 0.14762014 | F13: 0.081712948 | G13: =AVERAGE(B13:F13) -> 0.12420805 | J13: 0.10067641 | K13: 0.19320702 | L13: 0.14528625 | M13: 0.09421182 | N13: 0.18738235 | O13: =AVERAGE(J13:N13) -> 0.14415277
A14: 2007 | B14: 0.2104672 | C14: 0.25759687 | D14: 0.18058871 | E14: 0.21740526 | F14: 0.17498457 | G14: =AVERAGE(B14:F14) -> 0.20820852 | J14: 0.20652609 | K14: 0.15808861 | L14: 0.10466917 | M14: 0.12950889 | N14: 0.13712811 | O14: =AVERAGE(J14:N14) -> 0.14718417
... A30: 3012 | B30: 0.16352815 | C30: 0.2061542 | D30: 0.094027623 | E30: 0.19996867 | F30: 0.16026543 | G30: =AVERAGE(B30:F30) -> 0.16478882 | J30: 0.1880069 | K30: 0.13936784 | L30: 0.15296993 | M30: 0.13507815 | N30: 0.16692135 | O30: =AVERAGE(J30:N30) -> 0.15646883

Sheet 1st 5 Trials - SMALL
A1: Subject | B1: 1-small | C1: 1-small | D1: 1-small | E1: 2-small | F1: 2-small | G1: 2-small | H1: 3-small | I1: 3-small | J1: 3-small | K1: 4-small | L1: 4-small | M1: 4-small | N1: 5-small | O1: 5-small | P1: 5-small | Q1: AVERAGE ES1 | R1: *Overall Avg
A2: 1001 | B2: 0.16541662 | C2: 0.17069059 | D2: 0.10268824 | E2: 0.13400887 | F2: 0.19006743 | G2: 0.6501852 | H2: 0.17286104 | I2: 0.14677391 | J2: 0.16394759 | K2: 0.15275926 | L2: 0.15530988 | M2: 0.08832682 | N2: 0.16470187 | O2: 0.14075404 | P2: 0.10263775 | Q2: =AVERAGE(B2:P2) -> 0.18007527 | R2: =AVERAGE(Q2:Q30) -> 0.13411185
A3: 1002 | B3: 0.067178422 | C3: 0.10867784 | D3: 0.091439057 | E3: 0.11514924 | F3: 0.11605231 | G3: 0.066298094 | H3: 0.13746594 | I3: 0.11301612 | J3: 0.099954968 | K3: 0.1359221 | L3: 0.079281899 | M3: 0.092097846 | N3: 0.11661604 | O3: 0.22232634 | P3: 0.12798069 | Q3: =AVERAGE(B3:P3) -> 0.11263046
A4: 1003 | B4: 0.11944419 | C4: 0.10870727 | D4: 0.089765549 | E4: 0.099636054 | F4: 0.084602136 | G4: 0.083178221 | H4: 0.11215281 | I4: 0.10461987 | J4: 0.15574417 | K4: 0.16945003 | L4: 0.10202067 | M4: 0.066493286 | N4: 0.10966244 | O4: 0.1150739 | P4: 0.1042898 | Q4: =AVERAGE(B4:P4) -> 0.10832269
A5: 1004 | B5: 0.083056822 | C5: 0.10619549 | D5: 0.098339623 | E5: 0.11319122 | F5: 0.11212452 | G5: 0.08836784 | H5: 0.095937747 | I5: 0.086894944 | J5: 0.100819 | K5: 0.0858807 | L5: 0.11504754 | M5: 0.15099344 | N5: 0.12341651 | O5: 0.077164893 | P5: 0.099235102 | Q5: =AVERAGE(B5:P5) -> 0.10244436
A6: 1005 | B6: 0.19265655 | C6: 0.11756261 | D6: 0.14895586 | E6: 0.10651623 | F6: 0.13227125 | G6: 0.14356831 | H6: 0.14019959 | I6: 0.10224469 | J6: 0.36170175 | K6: 0.13069213 | L6: 0.12636893 | M6: 0.10615396 | N6: 0.22787865 | O6: 0.14832453 | P6: 0.16987582 | Q6: =AVERAGE(B6:P6) -> 0.15699806
A7: 1006 | B7: 0.12501424 | C7: 0.10187209 | D7: 0.096088629 | E7: 0.12928132 | F7: 0.098363567 | G7: 0.14581067 | H7: 0.10416164 | I7: 0.13241189 | J7: 0.094165846 | K7: 0.11035313 | L7: 0.13657669 | M7: 0.11902785 | N7: 0.10889396 | O7: 0.11233632 | P7: 0.10401465 | Q7: =AVERAGE(B7:P7) -> 0.11455817
A8: 1009 | B8: 0.28393427 | C8: 0.15533867 | D8: 0.18122882 | E8: 0.12473852 | F8: 0.11009057 | G8: 0.18722595 | H8: 0.2250994 | I8: 0.15178566 | J8: 0.18095388 | K8: 0.19168692 | L8: 0.2643369 | M8: 0.16235031 | N8: 0.26154017 | O8: 0.12324387 | P8: 0.13489944 | Q8: =AVERAGE(B8:P8) -> 0.18256356
A9: 2001 | B9: 0.1285095 | C9: 0.16288007 | D9: 0.1148556 | E9: 0.12891951 | F9: 0.1113112 | G9: 0.1793222 | H9: 0.23076807 | I9: 0.13901437 | J9: 0.14070322 | K9: 0.1207689 | L9: 0.14833555 | M9: 0.076908109 | N9: 0.17539138 | O9: 0.11671374 | P9: 0.15336886 | Q9: =AVERAGE(B9:P9) -> 0.14185135
A10: 2002 | B10: 0.11385653 | C10: 0.12937239 | D10: 0.10662253 | E10: 0.062540927 | F10: 0.080998152 | G10: 0.084893833 | H10: 0.094503937 | I10: 0.055623445 | J10: 0.089441422 | K10: 0.087290883 | L10: 0.091298173 | M10: 0.051398517 | N10: 0.10277854 | O10: 0.087169136 | P10: 0.13057308 | Q10: =AVERAGE(B10:P10) -> 0.0912241
A11: 2004 | B11: 0.15457864 | C11: 0.22935637 | D11: 0.10584312 | E11: 0.11643908 | F11: 0.14859805 | G11: 0.14797042 | H11: 0.14136619 | I11: 0.45243671 | J11: 0.12037853 | K11: 0.20575279 | L11: 0.1050083 | M11: 0.33011812 | N11: 0.15377784 | O11: 0.13983069 | P11: 0.22366127 | Q11: =AVERAGE(B11:P11) -> 0.18500774
A12: 2005 | B12: 0.087928687 | C12: 0.11250905 | D12: 0.15783563 | E12: 0.13486631 | F12: 0.25695383 | G12: 0.11571317 | H12: 0.18101376 | I12: 0.24381151 | J12: 0.35693839 | K12: 0.21891286 | L12: 0.26170139 | M12: 0.27057288 | N12: 0.15601473 | O12: 0.12493463 | P12: 0.21076356 | Q12: =AVERAGE(B12:P12) -> 0.19269803
A13: 2006 | B13: 0.15191407 | C13: 0.091856016 | D13: 0.077517242 | E13: 0.066151973 | F13: 0.074297174 | G13: 0.16011634 | H13: 0.10676447 | I13: 0.13243543 | J13: 0.095345828 | K13: 0.17463376 | L13: 0.087904809 | M13: 0.19826625 | N13: 0.11513844 | O13: 0.11035251 | P13: 0.14896723 | Q13: =AVERAGE(B13:P13) -> 0.1194441
A14: 2007 | B14: 0.080118206 | C14: 0.15034415 | D14: 0.11912076 | E14: 0.12579686 | F14: 0.16419523 | G14: 0.12069376 | H14: 0.12724774 | I14: 0.098474497 | J14: 0.088285456 | K14: 0.1354953 | L14: 0.14095564 | M14: 0.1065471 | N14: 0.22866872 | O14: 0.1098558 | P14: 0.20770153 | Q14: =AVERAGE(B14:P14) -> 0.13356672
... A30: 3012 | B30: 0.17384487 | C30: 0.088414782 | D30: 0.077795069 | E30: 0.11622277 | F30: 0.19124109 | G30: 0.082434673 | H30: 0.11487685 | I30: 0.09370128 | J30: 0.13278764 | K30: 0.19179669 | L30: 0.13965843 | M30: 0.14958683 | N30: 0.18001479 | O30: 0.16096301 | P30: 0.16411251 | Q30: =AVERAGE(B30:P30) -> 0.13716342

Sheet 2nd 5 Trials - SMALL
A1: Subject | B1: 6-small | C1: 6-small | D1: 6-small | E1: 7-small | F1: 7-small | G1: 7-small | H1: 8-small | I1: 8-small | J1: 8-small | K1: 9-small | L1: 9-small | M1: 9-small | N1: 10-small | O1: 10-small | P1: 10-small | Q1: AVERAGE ES2 | R1: *Overall Avg
A2: 1001 | B2: 0.12207708 | C2: 0.15330666 | D2: 0.090786048 | E2: 0.17023804 | F2: 0.24367015 | G2: 0.29240265 | H2: 0.13917726 | I2: 0.10067171 | J2: 0.057720278 | K2: 0.18588638 | L2: 0.091727169 | M2: 0.076969402 | N2: 0.19188846 | O2: 0.080525615 | P2: 0.10492891 | Q2: =AVERAGE(B2:P2) -> 0.14013172 | R2: =AVERAGE(Q2:Q30) -> 0.14064852
A3: 1002 | B3: 0.24773734 | C3: 0.11864123 | D3: 0.1151131 | E3: 0.11794525 | F3: 0.12861379 | G3: 0.1626917 | H3: 0.13419695 | I3: 0.14826459 | J3: 0.083278541 | K3: 0.061964892 | L3: 0.14784821 | M3: 0.10988897 | N3: 0.15677004 | O3: 0.091025189 | P3: 0.26410978 | Q3: =AVERAGE(B3:P3) -> 0.13920597
A4: 1003 | B4: 0.17172811 | C4: 0.075166296 | D4: 0.090432682 | E4: 0.16432345 | F4: 0.11725793 | G4: 0.11856086 | H4: 0.079133295 | I4: 0.10659919 | J4: 0.11604466 | K4: 0.18988394 | L4: 0.090287918 | M4: 0.1153271 | N4: 0.081121084 | O4: 0.15431908 | P4: 0.12832091 | Q4: =AVERAGE(B4:P4) -> 0.11990043
A5: 1004 | B5: 0.078313939 | C5: 0.12563981 | D5: 0.20211508 | E5: 0.12517278 | F5: 0.14769458 | G5: 0.17439203 | H5: 0.12507898 | I5: 0.14279021 | J5: 0.082188698 | K5: 0.11994382 | L5: 0.12465961 | M5: 0.11283937 | N5: 0.11740761 | O5: 0.087414528 | P5: 0.14627687 | Q5: =AVERAGE(B5:P5) -> 0.12746186
A6: 1005 | B6: 0.18292922 | C6: 0.1056764 | D6: 0.18301776 | E6: 0.067827357 | F6: 0.14082247 | G6: 0.17427631 | H6: 0.18228842 | I6: 0.13427896 | J6: 0.20457619 | K6: 0.15447721 | L6: 0.16222304 | M6: 0.16109313 | N6: 0.14144819 | O6: 0.14016307 | P6: 0.21985352 | Q6: =AVERAGE(B6:P6) -> 0.15699675
A7: 1006 | B7: 0.11739812 | C7: 0.11250104 | D7: 0.083814393 | E7: 0.072538124 | F7: 0.086090451 | G7: 0.096915219 | H7: 0.19808597 | I7: 0.10000529 | J7: 0.088945408 | K7: 0.15408811 | L7: 0.10011146 | M7: 0.088543393 | N7: 0.11398821 | O7: 0.11980292 | P7: 0.12720622 | Q7: =AVERAGE(B7:P7) -> 0.11066896
A8: 1009 | B8: 0.19103323 | C8: 0.17972842 | D8: 0.19526899 | E8: 0.2030808 | F8: 0.12807828 | G8: 0.10206487 | H8: 0.13052773 | I8: 0.1407434 | J8: 0.16598114 | K8: 0.16583619 | L8: 0.11134569 | M8: 0.1188501 | N8: 0.15949254 | O8: 0.14523756 | P8: 0.15693914 | Q8: =AVERAGE(B8:P8) -> 0.15294721
A9: 2001 | B9: 0.1722872 | C9: 0.1072521 | D9: 0.18200874 | E9: 0.23429562 | F9: 0.14811396 | G9: 0.25913772 | H9: 0.095916471 | I9: 0.12883261 | J9: 0.1802706 | K9: 0.12816057 | L9: 0.16247591 | M9: 0.11342808 | N9: 0.12198125 | O9: 0.19602195 | P9: 0.12427584 | Q9: =AVERAGE(B9:P9) -> 0.15696391
A10: 2002 | B10: 0.10687993 | C10: 0.096847889 | D10: 0.087054451 | E10: 0.12011253 | F10: 0.079464876 | G10: 0.070906771 | H10: 0.13818146 | I10: 0.067379646 | J10: 0.1113714 | K10: 0.22403822 | L10: 0.10724549 | M10: 0.06613776 | N10: 0.116027 | O10: 0.091602865 | P10: 0.13201664 | Q10: =AVERAGE(B10:P10) -> 0.10768446
A11: 2004 | B11: 0.11465288 | C11: 0.30316058 | D11: 0.13787395 | E11: 0.17244175 | F11: 0.15418704 | G11: 0.1809285 | H11: 0.19776634 | I11: 0.17768419 | J11: 0.18023685 | K11: 0.099553719 | L11: 0.15496493 | M11: 0.14432684 | N11: 0.19386418 | O11: 0.12898152 | P11: 0.14476178 | Q11: =AVERAGE(B11:P11) -> 0.16569234
A12: 2005 | B12: 0.2282496 | C12: 0.1362928 | D12: 0.1540589 | E12: 0.086616932 | F12: 0.26569688 | G12: 0.19694876 | H12: 0.11369217 | I12: 0.17307411 | J12: 0.22341748 | K12: 0.18437017 | L12: 0.14493336 | M12: 0.28393603 | N12: 0.1332139 | O12: 0.12885111 | P12: 0.16913837 | Q12: =AVERAGE(B12:P12) -> 0.17483271
A13: 2006 | B13: 0.091859183 | C13: 0.080146776 | D13: 0.23375954 | E13: 0.11302532 | F13: 0.13022483 | G13: 0.093832432 | H13: 0.11529371 | I13: 0.074775519 | J13: 0.21743365 | K13: 0.14328425 | L13: 0.098473983 | M13: 0.095538953 | N13: 0.076577981 | O13: 0.11404948 | P13: 0.080821217 | Q13: =AVERAGE(B13:P13) -> 0.11727312
A14: 2007 | B14: 0.099200189 | C14: 0.10783367 | D14: 0.16743276 | E14: 0.17598833 | F14: 0.16020146 | G14: 0.25017923 | H14: 0.16776881 | I14: 0.16430001 | J14: 0.23944711 | K14: 0.12305633 | L14: 0.17915493 | M14: 0.093334724 | N14: 0.090369694 | O14: 0.16367562 | P14: 0.16051043 | Q14: =AVERAGE(B14:P14) -> 0.15616355
... A30: 3012 | B30: 0.19749587 | C30: 0.23747907 | D30: 0.1254718 | E30: 0.17461577 | F30: 0.13240926 | G30: 0.19456423 | H30: 0.31104186 | I30: 0.10524765 | J30: 0.11593679 | K30: 0.21289341 | L30: 0.13896973 | M30: 0.1847604 | N30: 0.22547544 | O30: 0.13947281 | P30: 0.15140371 | Q30: =AVERAGE(B30:P30) -> 0.17648252

Sheet Raw Error Scores
C1: 1001 | D1: 1002 | E1: 1003 | F1: 1004 | G1: 1005 | H1: 1006 | I1: 1009 | J1: 2001 | K1: 2002 | L1: 2004 | M1: 2005 | N1: 2006 | O1: 2007 | P1: 2008 | Q1: 2009 | R1: 2010 | S1: 2011 | T1: 2012 | U1: 3001 | V1: 3002 | W1: 3003 | X1: 3004 | Y1: 3006 | Z1: 3007 | AA1: 3008 | AB1: 3009 | AC1: 3010 | AD1: 3011 | AE1: 3012
A2: 1 | B2: B | C2: 0.13173304 | D2: 0.13504829 | E2: 0.12339935 | F2: 0.15713296 | G2: 0.24656209 | H2: 0.14107662 | I2: 0.13265165 | J2: 0.19984035 | K2: 0.091655251 | L2: 0.20239901 | M2: 0.17650195 | N2: 0.13405422 | O2: 0.2104672 | P2: 0.27285437 | Q2: 0.14008916 | R2: 0.2129343 | S2: 0.23990273 | T2: 0.10696794 | U2: 0.20041066 | V2: 0.11609809 | W2: 0.13780217 | X2: 0.1279507 | Y2: 0.097717341 | Z2: 0.18554909 | AA2: 0.17234625 | AB2: 0.11921777 | AC2: 0.22442086 | AD2: 0.10243489 | AE2: 0.16352815
B3: smalls | C3: 0.16541662 | D3: 0.067178422 | E3: 0.11944419 | F3: 0.083056822 | G3: 0.19265655 | H3: 0.12501424 | I3: 0.28393427 | J3: 0.1285095 | K3: 0.11385653 | L3: 0.15457864 | M3: 0.087928687 | N3: 0.15191407 | O3: 0.080118206 | P3: 0.24519884 | Q3: 0.12055078 | R3: 0.19860052 | S3: 0.12589574 | T3: 0.16919379 | U3: 0.16256251 | V3: 0.099510192 | W3: 0.073216272 | X3: 0.076247284 | Y3: 0.10215978 | Z3: 0.13916143 | AA3: 0.12065577 | AB3: 0.079999567 | AC3: 0.30651692 | AD3: 0.06940677 | AE3: 0.17384487
C4: 0.17069059 | D4: 0.10867784 | E4: 0.10870727 | F4: 0.10619549 | G4: 0.11756261 | H4: 0.10187209 | I4: 0.15533867 | J4: 0.16288007 | K4: 0.12937239 | L4: 0.22935637 | M4: 0.11250905 | N4: 0.091856016 | O4: 0.15034415 | P4: 0.42039657 | Q4: 0.088321715 | R4: 0.24990278 | S4: 0.11329008 | T4: 0.076848119 | U4: 0.14418209 | V4: 0.10958654 | W4: 0.091183659 | X4: 0.070749731 | Y4: 0.073796822 | Z4: 0.13700427 | AA4: 0.167417 | AB4: 0.11952391 | AC4: 0.20978357 | AD4: 0.086967927 | AE4: 0.088414782
C5: 0.10268824 | D5: 0.091439057 | E5: 0.089765549 | F5: 0.098339623 | G5: 0.14895586 | H5: 0.096088629 | I5: 0.18122882 | J5: 0.1148556 | K5: 0.10662253 | L5: 0.10584312 | M5: 0.15783563 | N5: 0.077517242 | O5: 0.11912076 | P5: 0.20407358 | Q5: 0.07658246 | R5: 0.26677557 | S5: 0.11143856 | T5: 0.10255464 | U5: 0.058164651 | V5: 0.088254014 | W5: 0.074541251 | X5: 0.11499028 | Y5: 0.10644905 | Z5: 0.16056988 | AA5: 0.11056147 | AB5: 0.070851093 | AC5: 0.1141872 | AD5: 0.087471035 | AE5: 0.077795069
A6: 2 | B6: B | C6: 0.11660398 | D6: 0.11818617 | E6: 0.13105264 | F6: 0.11182575 | G6: 0.22558313 | H6: 0.095371029 | I6: 0.11136392 | J6: 0.14678328 | K6: 0.048680984 | L6: 0.12164046 | M6: 0.12858856 | N6: 0.10279871 | O6: 0.25759687 | P6: 0.26791247 | Q6: 0.1250578 | R6: 0.18083833 | S6: 0.1199853 | T6: 0.14682842 | U6: 0.6238243 | V6: 0.071840752 | W6: 0.15833249 | X6: 0.11719123 | Y6: 0.076118852 | Z6: 0.14887795 | AA6: 0.12147274 | AB6: 0.085138548 | AC6: 0.15481048 | AD6: 0.078812422 | AE6: 0.2061542
B7: smalls | C7: 0.13400887 | D7: 0.11514924 | E7: 0.099636054 | F7: 0.11319122 | G7: 0.10651623 | H7: 0.12928132 | I7: 0.12473852 | J7: 0.12891951 | K7: 0.062540927 | L7: 0.11643908 | M7: 0.13486631 | N7: 0.066151973 | O7: 0.12579686 | P7: 0.22888329 | Q7: 0.10117133 | R7: 0.17401359 | S7: 0.084935851 | T7: 0.12450234 | U7: 0.15299751 | V7: 0.057412635 | W7: 0.15080095 | X7: 0.14926214 | Y7: 0.10079691 | Z7: 0.17557394 | AA7: 0.10740453 | AB7: 0.1082452 | AC7: 0.17568171 | AD7: 0.068756015 | AE7: 0.11622277
C8: 0.19006743 | D8: 0.11605231 | E8: 0.084602136 | F8: 0.11212452 | G8: 0.13227125 | H8: 0.098363567 | I8: 0.11009057 | J8: 0.1113112 | K8: 0.080998152 | L8: 0.14859805 | M8: 0.25695383 | N8: 0.074297174 | O8: 0.16419523 | P8: 0.32231107 | Q8: 0.11683914 | R8: 0.13028324 | S8: 0.10157392 | T8: 0.1138534 | U8: 0.12259247 | V8: 0.051263371 | W8: 0.10290222 | X8: 0.099509436 | Y8: 0.099161651 | Z8: 0.10841886 | AA8: 0.086459837 | AB8: 0.11403931 | AC8: 0.16167811 | AD8: 0.063487188 | AE8: 0.19124109
C9: 0.6501852 | D9: 0.066298094 | E9: 0.083178221 | F9: 0.08836784 | G9: 0.14356831 | H9: 0.14581067 | I9: 0.18722595 | J9: 0.1793222 | K9: 0.084893833 | L9: 0.14797042 | M9: 0.11571317 | N9: 0.16011634 | O9: 0.12069376 | P9: 0.20486975 | Q9: 0.11845436 | R9: 0.17021813 | S9: 0.12587489 | T9: 0.14366208 | U9: 0.099704309 | V9: 0.066753559 | W9: 0.077959527 | X9: 0.076348875 | Y9: 0.079893895 | Z9: 0.066240559 | AA9: 0.11069644 | AB9: 0.17618482 | AC9: 0.11797792 | AD9: 0.10950266 | AE9: 0.082434673
A10: 3 | B10: B | C10: 0.090370552 | D10: 0.1802386 | E10: 0.07670827 | F10: 0.10825938 | G10: 0.14854598 | H10: 0.11994663 | I10: 0.091864787 | J10: 0.22878195 | K10: 0.095660613 | L10: 0.23332518 | M10: 0.13832724 | N10: 0.15485423 | O10: 0.18058871 | P10: 0.3462945 | Q10: 0.17185679 | R10: 0.16632603 | S10: 0.08731564 | T10: 0.13520409 | U10: 0.11562561 | V10: 0.086780794 | W10: 0.12363267 | X10: 0.1265376 | Y10: 0.090136791 | Z10: 0.13555448 | AA10: 0.12705254 | AB10: 0.088576429 | AC10: 0.18934177 | AD10: 0.11171322 | AE10: 0.094027623
B11: smalls | C11: 0.17286104 | D11: 0.13746594 | E11: 0.11215281 | F11: 0.095937747 | G11: 0.14019959 | H11: 0.10416164 | I11: 0.2250994 | J11: 0.23076807 | K11: 0.094503937 | L11: 0.14136619 | M11: 0.18101376 | N11: 0.10676447 | O11: 0.12724774 | P11: 0.60755812 | Q11: 0.14359047 | R11: 0.15832686 | S11: 0.096610121 | T11: 0.14606322 | U11: 0.10138664 | V11: 0.069387185 | W11: 0.10367869 | X11: 0.13802929 | Y11: 0.063541172 | Z11: 0.15516695 | AA11: 0.12790375 | AB11: 0.074959702 | AC11: 0.23123561 | AD11: 0.095460934 | AE11: 0.11487685
C12: 0.14677391 | D12: 0.11301612 | E12: 0.10461987 | F12: 0.086894944 | G12: 0.10224469 | H12: 0.13241189 | I12: 0.15178566 | J12: 0.13901437 | K12: 0.055623445 | L12: 0.45243671 | M12: 0.24381151 | N12: 0.13243543 | O12: 0.098474497 | P12: 0.40564749 | Q12: 0.18714407 | R12: 0.16512428 | S12: 0.08026567 | T12: 0.16378995 | U12: 0.12894099 | V12: 0.058112723 | W12: 0.083426758 | X12: 0.13303443 | Y12: 0.14522092 | Z12: 0.095163654 | AA12: 0.10967484 | AB12: 0.089418618 | AC12: 0.15667353 | AD12: 0.0999901 | AE12: 0.09370128
C13: 0.16394759 | D13: 0.099954968 | E13: 0.15574417 | F13: 0.100819 | G13: 0.36170175 | H13: 0.094165846 | I13: 0.18095388 | J13: 0.14070322 | K13: 0.089441422 | L13: 0.12037853 | M13: 0.35693839 | N13: 0.095345828 | O13: 0.088285456 | P13: 0.15878296 | Q13: 0.11657998 | R13: 0.13646813 | S13: 0.062794543 | T13: 0.11248299 | U13: 0.16560105 | V13: 0.050628232 | W13: 0.055749728 | X13: 0.12643154 | Y13: 0.085536089 | Z13: 0.17209536 | AA13: 0.11192937 | AB13: 0.14843096 | AC13: 0.13611243 | AD13: 0.06369505 | AE13: 0.13278764
A14: 4 | B14: B | C14: 0.13229509 | D14: 0.14626103 | E14: 0.096860685 | F14: 0.15204033 | G14: 0.32167207 | H14: 0.21010114 | I14: 0.087749839 | J14: 0.14922342 | K14: 0.091094807 | L14: 0.18527961 | M14: 0.17572404 | N14: 0.14762014 | O14: 0.21740526 | P14: 0.30377699 | Q14: 0.17381074 | R14: 0.16682237 | S14: 0.10932705 | T14: 0.13590069 | U14: 0.13141047 | V14: 0.064643194 | W14: 0.1084525 | X14: 0.11198468 | Y14: 0.11291232 | Z14: 0.13095824 | AA14: 0.10465615 | AB14: 0.12202748 | AC14: 0.19179275 | AD14: 0.11781258 | AE14: 0.19996867
B15: smalls | C15: 0.15275926 | D15: 0.1359221 | E15: 0.16945003 | F15: 0.0858807 | G15: 0.13069213 | H15: 0.11035313 | I15: 0.19168692 | J15: 0.1207689 | K15: 0.087290883 | L15: 0.20575279 | M15: 0.21891286 | N15: 0.17463376 | O15: 0.1354953 | P15: 0.25449045 | Q15: 0.12469285 | R15: 0.083826451 | S15: 0.10045957 | T15: 0.086083415 | U15: 0.16294797 | V15: 0.059728937 | W15: 0.080297761 | X15: 0.10672174 | Y15: 0.08340034 | Z15: 0.19660609 | AA15: 0.13715372 | AB15: 0.14363951 | AC15: 0.32518518 | AD15: 0.10282172 | AE15: 0.19179669
C16: 0.15530988 | D16: 0.079281899 | E16: 0.10202067 | F16: 0.11504754 | G16: 0.12636893 | H16: 0.13657669 | I16: 0.2643369 | J16: 0.14833555 | K16: 0.091298173 | L16: 0.1050083 | M16: 0.26170139 | N16: 0.087904809 | O16: 0.14095564 | P16: 0.1641923 | Q16: 0.19209873 | R16: 0.17922044 | S16: 0.096342483 | T16: 0.11337122 | U16: 0.1229741 | V16: 0.053743373 | W16: 0.14592564 | X16: 0.12830593 | Y16: 0.070824771 | Z16: 0.06058735 | AA16: 0.071867704 | AB16: 0.097284234 | AC16: 0.16987189 | AD16: 0.095529153 | AE16: 0.13965843
C17: 0.08832682 | D17: 0.092097846 | E17: 0.066493286 | F17: 0.15099344 | G17: 0.10615396 | H17: 0.11902785 | I17: 0.16235031 | J17: 0.076908109 | K17: 0.051398517 | L17: 0.33011812 | M17: 0.27057288 | N17: 0.19826625 | O17: 0.1065471 | P17: 0.28788615 | Q17: 0.14164607 | R17: 0.13579463 | S17: 0.076944685 | T17: 0.16816121 | U17: 0.1788314 | V17: 0.061200178 | W17: 0.080678439 | X17: 0.14436752 | Y17: 0.057659293 | Z17: 0.10065159 | AA17: 0.12952073 | AB17: 0.099460149 | AC17: 0.18987659 | AD17: 0.072825495 | AE17: 0.14958683
A18: 5 | B18: B | C18: 0.10434547 | D18: 0.17171695 | E18: 0.13342216 | F18: 0.11773584 | G18: 0.2835267 | H18: 0.2033395 | I18: 0.12144113 | J18: 0.26979082 | K18: 0.074365012 | L18: 0.18882089 | M18: 0.18992961 | N18: 0.081712948 | O18: 0.17498457 | P18: 0.36213429 | Q18: 0.15945766 | R18: 0.27562024 | S18: 0.151128 | T18: 0.11842008 | U18: 0.096200788 | V18: 0.096616184 | W18: 0.088146398 | X18: 0.15938051 | Y18: 0.12503163 | Z18: 0.10124466 | AA18: 0.15117422 | AB18: 0.1636099 | AC18: 0.1765669 | AD18: 0.12180504 | AE18: 0.16026543
B19: smalls | C19: 0.16470187 | D19: 0.11661604 | E19: 0.10966244 | F19: 0.12341651 | G19: 0.22787865 | H19: 0.10889396 | I19: 0.26154017 | J19: 0.17539138 | K19: 0.10277854 | L19: 0.15377784 | M19: 0.15601473 | N19: 0.11513844 | O19: 0.22866872 | P19: 0.23285977 | Q19: 0.2072344 | R19: 0.14320766 | S19: 0.079159709 | T19: 0.061095361 | U19: 0.20959614 | V19: 0.037924762 | W19: 0.081095796 | X19: 0.14898523 | Y19: 0.071676267 | Z19: 0.19505279 | AA19: 0.15870879 | AB19: 0.11219542 | AC19: 0.12907423 | AD19: 0.072272617 | AE19: 0.18001479
C20: 0.14075404 | D20: 0.22232634 | E20: 0.1150739 | F20: 0.077164893 | G20: 0.14832453 | H20: 0.11233632 | I20: 0.12324387 | J20: 0.11671374 | K20: 0.087169136 | L20: 0.13983069 | M20: 0.12493463 | N20: 0.11035251 | O20: 0.1098558 | P20: 0.18320309 | Q20: 0.12716164 | R20: 0.18750061 | S20: 0.067039454 | T20: 0.079640021 | U20: 0.1692489 | V20: 0.077205902 | W20: 0.093612287 | X20: 0.13524921 | Y20: 0.11159588 | Z20: 0.078479954 | AA20: 0.15753253 | AB20: 0.10748254 | AC20: 0.19648551 | AD20: 0.11208482 | AE20: 0.16096301
C21: 0.10263775 | D21: 0.12798069 | E21: 0.1042898 | F21: 0.099235102 | G21: 0.16987582 | H21: 0.10401465 | I21: 0.13489944 | J21: 0.15336886 | K21: 0.13057308 | L21: 0.22366127 | M21: 0.21076356 | N21: 0.14896723 | O21: 0.20770153 | P21: 0.22622979 | Q21: 0.13813573 | R21: 0.078174671 | S21: 0.078384745 | T21: 0.13696138 | U21: 0.096670019 | V21: 0.064431169 | W21: 0.10125707 | X21: 0.1077078 | Y21: 0.11142255 | Z21: 0.17257109 | AA21: 0.20532909 | AB21: 0.089284092 | AC21: 0.11762486 | AD21: 0.06459788 | AE21: 0.16411251
A22: 6 | B22: B | C22: 0.15963656 | D22: 0.28593262 | E22: 0.14854035 | F22: 0.20428442 | G22: 0.30996387 | H22: 0.14015374 | I22: 0.10911064 | J22: 0.2059181 | K22: 0.11781754 | L22: 0.11654828 | M22: 0.17644311 | N22: 0.10067641 | O22: 0.20652609 | P22: 0.82047797 | Q22: 0.23613076 | R22: 0.18557891 | S22: 0.21180792 | T22: 0.090676635 | U22: 0.074967808 | V22: 0.10156955 | W22: 0.20896289 | X22: 0.13109425 | Y22: 0.15074487 | Z22: 0.20935405 | AA22: 0.1278466 | AB22: 0.098785019 | AC22: 0.23297713 | AD22: 0.1015479 | AE22: 0.1880069
B23: smalls | C23: 0.12207708 | D23: 0.24773734 | E23: 0.17172811 | F23: 0.078313939 | G23: 0.18292922 | H23: 0.11739812 | I23: 0.19103323 | J23: 0.1722872 | K23: 0.10687993 | L23: 0.11465288 | M23: 0.2282496 | N23: 0.091859183 | O23: 0.099200189 | P23: 0.20826302 | Q23: 0.17256722 | R23: 0.12613936 | S23: 0.09581744 | T23: 0.11880108 | U23: 0.1637653 | V23: 0.058855883 | W23: 0.22496522 | X23: 0.11804321 | Y23: 0.1014568 | Z23: 0.12366077 | AA23: 0.1252381 | AB23: 0.088540012 | AC23: 0.35611287 | AD23: 0.1083351 | AE23: 0.19749587
C24: 0.15330666 | D24: 0.11864123 | E24: 0.075166296 | F24: 0.12563981 | G24: 0.1056764 | H24: 0.11250104 | I24: 0.17972842 | J24: 0.1072521 | K24: 0.096847889 | L24: 0.30316058 | M24: 0.1362928 | N24: 0.080146776 | O24: 0.10783367 | P24: 0.42471824 | Q24: 0.17430039 | R24: 0.1007203 | S24: 0.082724547 | T24: 0.10268448 | U24: 0.08149951 | V24: 0.054610763 | W24: 0.09500651 | X24: 0.11457865 | Y24: 0.066783711 | Z24: 0.076394561 | AA24: 0.055704032 | AB24: 0.12104362 | AC24: 0.22691147 | AD24: 0.091210328 | AE24: 0.23747907
C25: 0.090786048 | D25: 0.1151131 | E25: 0.090432682 | F25: 0.20211508 | G25: 0.18301776 | H25: 0.083814393 | I25: 0.19526899 | J25: 0.18200874 | K25: 0.087054451 | L25: 0.13787395 | M25: 0.1540589 | N25: 0.23375954 | O25: 0.16743276 | P25: 0.31782151 | Q25: 0.1502647 | R25: 0.12628753 | S25: 0.086386497 | T25: 0.15117478 | U25: 0.066012609 | V25: 0.063662811 | W25: 0.11498843 | X25: 0.097726021 | Y25: 0.070055359 | Z25: 0.19459536 | AA25: 0.090110932 | AB25: 0.1291761 | AC25: 0.092936045 | AD25: 0.067783641 | AE25: 0.1254718
A26: 7 | B26: B | C26: 0.16085642 | D26: 0.18884495 | E26: 0.097093793 | F26: 0.29777461 | G26: 0.19711092 | H26: 0.14131092 | I26: 0.092280788 | J26: 0.134352 | K26: 0.075890064 | L26: 0.14017408 | M26: 0.17442497 | N26: 0.19320702 | O26: 0.15808861 | P26: 0.38343894 | Q26: 0.19161681 | R26: 0.1518418 | S26: 0.09381119 | T26: 0.088811666 | U26: 0.15615273 | V26: 0.070950724 | W26: 0.15633351 | X26: 0.14291883 | Y26: 0.095674525 | Z26: 0.18531784 | AA26: 0.18195879 | AB26: 0.11959645 | AC26: 0.11364567 | AD26: 0.11578064 | AE26: 0.13936784
B27: smalls | C27: 0.17023804 | D27: 0.11794525 | E27: 0.16432345 | F27: 0.12517278 | G27: 0.067827357 | H27: 0.072538124 | I27: 0.2030808 | J27: 0.23429562 | K27: 0.12011253 | L27: 0.17244175 | M27: 0.086616932 | N27: 0.11302532 | O27: 0.17598833 | P27: 0.22440522 | Q27: 0.24137299 | R27: 0.14833061 | S27: 0.09861106 | T27: 0.070488844 | U27: 0.14815305 | V27: 0.08778497 | W27: 0.25278468 | X27: 0.091448406 | Y27: 0.074564638 | Z27: 0.11132447 | AA27: 0.19160421 | AB27: 0.10841927 | AC27: 0.16494364 | AD27: 0.064583907 | AE27: 0.17461577
C28: 0.24367015 | D28: 0.12861379 | E28: 0.11725793 | F28: 0.14769458 | G28: 0.14082247 | H28: 0.086090451 | I28: 0.12807828 | J28: 0.14811396 | K28: 0.079464876 | L28: 0.15418704 | M28: 0.26569688 | N28: 0.13022483 | O28: 0.16020146 | P28: 0.3031512 | Q28: 0.20483457 | R28: 0.25558547 | S28: 0.12341821 | T28: 0.15660476 | U28: 0.082643519 | V28: 0.06781602 | W28: 0.069321724 | X28: 0.052157302 | Y28: 0.095488786 | Z28: 0.15272863 | AA28: 0.13644072 | AB28: 0.16842897 | AC28: 0.16991737 | AD28: 0.071589425 | AE28: 0.13240926
C29: 0.29240265 | D29: 0.1626917 | E29: 0.11856086 | F29: 0.17439203 | G29: 0.17427631 | H29: 0.096915219 | I29: 0.10206487 | J29: 0.25913772 | K29: 0.070906771 | L29: 0.1809285 | M29: 0.19694876 | N29: 0.093832432 | O29: 0.25017923 | P29: 0.24114498 | Q29: 0.25156993 | R29: 0.16993028 | S29: 0.12257302 | T29: 0.1522039 | U29: 0.098405439 | V29: 0.080923111 | W29: 0.10598043 | X29: 0.10356471 | Y29: 0.072834585 | Z29: 0.18385981 | AA29: 0.090714849 | AB29: 0.17356391 | AC29: 0.11746935 | AD29: 0.081706157 | AE29: 0.19456423
A30: 8 | B30: B | C30: 0.26858141 | D30: 0.1660469 | E30: 0.12880761 | F30: 0.17166907 | G30: 0.22993667 | H30: 0.098478455 | I30: 0.061224072 | J30: 0.098045124 | K30: 0.14253978 | L30: 0.16489609 | M30: 0.16373005 | N30: 0.14528625 | O30: 0.10466917 | P30: 0.27919553 | Q30: 0.16440554 | R30: 0.17182321 | S30: 0.13784741 | T30: 0.11126917 | U30: 0.16361721 | V30: 0.1016033 | W30: 0.11326037 | X30: 0.10444112 | Y30: 0.079492706 | Z30: 0.14023187 | AA30: 0.12411984 | AB30: 0.17441309 | AC30: 0.22562471 | AD30: 0.070103976 | AE30: 0.15296993
B31: smalls | C31: 0.13917726 | D31: 0.13419695 | E31: 0.079133295 | F31: 0.12507898 | G31: 0.18228842 | H31: 0.19808597 | I31: 0.13052773 | J31: 0.095916471 | K31: 0.13818146 | L31: 0.19776634 | M31: 0.11369217 | N31: 0.11529371 | O31: 0.16776881 | P31: 0.42836588 | Q31: 0.22435225 | R31: 0.13053411 | S31: 0.082616436 | T31: 0.067163177 | U31: 0.11661053 | V31: 0.08071484 | W31: 0.1560956 | X31: 0.10600992 | Y31: 0.052640687 | Z31: 0.14655361 | AA31: 0.19861136 | AB31: 0.10351436 | AC31: 0.16227772 | AD31: 0.085051336 | AE31: 0.31104186
C32: 0.10067171 | D32: 0.14826459 | E32: 0.10659919 | F32: 0.14279021 | G32: 0.13427896 | H32: 0.10000529 | I32: 0.1407434 | J32: 0.12883261 | K32: 0.067379646 | L32: 0.17768419 | M32: 0.17307411 | N32: 0.074775519 | O32: 0.16430001 | P32: 0.12096633 | Q32: 0.069351313 | R32: 0.29354422 | S32: 0.15631942 | T32: 0.077487405 | U32: 0.10734222 | V32: 0.10541792 | W32: 0.093703697 | X32: 0.105636 | Y32: 0.096356144 | Z32: 0.11065481 | AA32: 0.16587124 | AB32: 0.15873098 | AC32: 0.11300452 | AD32: 0.083940332 | AE32: 0.10524765
C33: 0.057720278 | D33: 0.083278541 | E33: 0.11604466 | F33: 0.082188698 | G33: 0.20457619 | H33: 0.088945408 | I33: 0.16598114 | J33: 0.1802706 | K33: 0.1113714 | L33: 0.18023685 | M33: 0.22341748 | N33: 0.21743365 | O33: 0.23944711 | P33: 0.28632053 | Q33: 0.21138456 | R33: 0.12369499 | S33: 0.12206638 | T33: 0.085813661 | U33: 0.099796236 | V33: 0.054232978 | W33: 0.093189126 | X33: 0.14081197 | Y33: 0.11828403 | Z33: 0.1835311 | AA33: 0.14393563 | AB33: 0.16602048 | AC33: 0.15954899 | AD33: 0.087469793 | AE33: 0.11593679
A34: 9 | B34: B | C34: 0.15802816 | D34: 0.1185581 | E34: 0.1942474 | F34: 0.15634473 | G34: 0.17911651 | H34: 0.10739508 | I34: 0.11219267 | J34: 0.11231239 | K34: 0.11248296 | L34: 0.19508766 | M34: 0.27261806 | N34: 0.09421182 | O34: 0.12950889 | P34: 0.37437891 | Q34: 0.13102058 | R34: 0.13226141 | S34: 0.16124158 | T34: 0.11367357 | U34: 0.22470732 | V34: 0.059948545 | W34: 0.09804662 | X34: 0.15757313 | Y34: 0.10069733 | Z34: 0.13840529 | AA34: 0.61428454 | AB34: 0.10775339 | AC34: 0.16015399 | AD34: 0.096784439 | AE34: 0.13507815
B35: smalls | C35: 0.18588638 | D35: 0.061964892 | E35: 0.18988394 | F35: 0.11994382 | G35: 0.15447721 | H35: 0.15408811 | I35: 0.16583619 | J35: 0.12816057 | K35: 0.22403822 | L35: 0.099553719 | M35: 0.18437017 | N35: 0.14328425 | O35: 0.12305633 | P35: 0.35191818 | Q35: 0.19820792 | R35: 0.15903183 | S35: 0.14997069 | T35: 0.10646577 | U35: 0.14652487 | V35: 0.059171718 | W35: 0.082331956 | X35: 0.14955072 | Y35: 0.08519062 | Z35: 0.11471614 | AA35: 0.14228336 | AB35: 0.16192883 | AC35: 0.18980556 | AD35: 0.073880924 | AE35: 0.21289341
C36: 0.091727169 | D36: 0.14784821 | E36: 0.090287918 | F36: 0.12465961 | G36: 0.16222304 | H36: 0.10011146 | I36: 0.11134569 | J36: 0.16247591 | K36: 0.10724549 | L36: 0.15496493 | M36: 0.14493336 | N36: 0.098473983 | O36: 0.17915493 | P36: 0.300265 | Q36: 0.23795002 | R36: 0.18145875 | S36: 0.091471468 | T36: 0.10241197 | U36: 0.11126623 | V36: 0.075604956 | W36: 0.086143685 | X36: 0.11904841 | Y36: 0.12187043 | Z36: 0.117443 | AA36: 0.30852484 | AB36: 0.15668594 | AC36: 0.11084553 | AD36: 0.068121306 | AE36: 0.13896973
C37: 0.076969402 | D37: 0.10988897 | E37: 0.1153271 | F37: 0.11283937 | G37: 0.16109313 | H37: 0.088543393 | I37: 0.1188501 | J37: 0.11342808 | K37: 0.06613776 | L37: 0.14432684 | M37: 0.28393603 | N37: 0.095538953 | O37: 0.093334724 | P37: 0.62730193 | Q37: 0.1375139 | R37: 0.16592023 | S37: 0.098248408 | T37: 0.095444507 | U37: 0.19799914 | V37: 0.07197504 | W37: 0.10629104 | X37: 0.10043022 | Y37: 0.064005858 | Z37: 0.18133499 | AA37: 0.14452449 | AB37: 0.13493723 | AC37: 0.075683561 | AD37: 0.089682089 | AE37: 0.1847604
A38: 10 | B38: B | C38: 0.15962206 | D38: 0.090679093 | E38: 0.13287769 | F38: 0.091094742 | G38: 0.21262054 | H38: 0.15408767 | I38: 0.065775546 | J38: 0.16600645 | K38: 0.13195246 | L38: 0.10064801 | M38: 0.17659158 | N38: 0.18738235 | O38: 0.13712811 | P38: 0.37864767 | Q38: 0.49377684 | R38: 0.18976709 | S38: 0.13379227 | T38: 0.14618606 | U38: 0.24043881 | V38: 0.079408546 | W38: 0.11637358 | X38: 0.14309659 | Y38: 0.08823399 | Z38: 0.1796951 | AA38: 0.27787931 | AB38: 0.099067671 | AC38: 0.14258311 | AD38: 0.10907946 | AE38: 0.16692135
B39: smalls | C39: 0.19188846 | D39: 0.15677004 | E39: 0.081121084 | F39: 0.11740761 | G39: 0.14144819 | H39: 0.11398821 | I39: 0.15949254 | J39: 0.12198125 | K39: 0.116027 | L39: 0.19386418 | M39: 0.1332139 | N39: 0.076577981 | O39: 0.090369694 | P39: 0.35415386 | Q39: 0.21266265 | R39: 0.14012753 | S39: 0.11236822 | T39: 0.10490419 | U39: 0.18307232 | V39: 0.039719887 | W39: 0.1746732 | X39: 0.1272252 | Y39: 0.059497535 | Z39: 0.17704544 | AA39: 0.16576075 | AB39: 0.10994695 | AC39: 0.26501356 | AD39: 0.086423345 | AE39: 0.22547544
C40: 0.080525615 | D40: 0.091025189 | E40: 0.15431908 | F40: 0.087414528 | G40: 0.14016307 | H40: 0.11980292 | I40: 0.14523756 | J40: 0.19602195 | K40: 0.091602865 | L40: 0.12898152 | M40: 0.12885111 | N40: 0.11404948 | O40: 0.16367562 | P40: 0.23747519 | Q40: 0.11544878 | R40: 0.076018828 | S40: 0.1108807 | T40: 0.1614056 | U40: 0.12844989 | V40: 0.073778396 | W40: 0.11115718 | X40: 0.09203892 | Y40: 0.10886338 | Z40: 0.11330262 | AA40: 0.14613795 | AB40: 0.14122054 | AC40: 0.11034623 | AD40: 0.064179772 | AE40: 0.13947281
...
